<?xml version="1.0"?>
<robot name="eeduro_delta">


<link name="world"/>

<joint name="fix_to_world" type="fixed">
	<parent link="world"/>
	<child link="base_link"/>
<!--	<origin/> -->
</joint>

<link name="base_link">
	<visual>
		<geometry>
			<mesh filename="package://eeduro_delta_description/meshes/delta_base.dae"/>
				<!--<box size="0.2 0.2 0.2"/>-->
		</geometry>
	</visual>
	<collision>
		<!-- only for box <origin xyz="0 0.03 0.01"/> --> 
		<geometry>
			<mesh filename="package://eeduro_delta_description/meshes/delta_base_collision.dae"/>
			<!--<box size="0.23 0.2 0.02"/>-->
		</geometry>
	</collision>
	<inertial>
		<origin xyz="-3.61483029333e-10 0.0127334577336 0.0879729092856" rpy="0 0 0"/>
		<mass value="1.9"/>
		<inertia	ixx="0.02085588597106"
							ixy="-1.660569664432e-10"
							ixz="-1.1398676896544e-10"
							iyy="0.02129590096144"
							iyz="0.0016993275934572"
							izz="0.019156198852616"/>
	</inertial>
</link>

<joint name="joint_motor_arm1" type="continuous">
	<parent link="base_link"/>
	<child link="link_motor_arm1"/>
	<origin xyz="0.04 -0.052735026919 0.195" rpy="-1.570796327 0 3.141592654"/>
	<axis xyz="1 0 0"/>
	<dynamics damping="0.0000001"/>
</joint>

<link name="link_motor_arm1">
	<visual>
    <origin xyz="0 0 0" rpy="0 1.570796327 0"/>
    <geometry>
      <cylinder radius="0.006" length="0.018"/>
    </geometry>
  </visual>
  <inertial>
    <origin xyz="0 0 0" rpy="0 0 0"/>
    <mass value="0.01"/>
    <inertia ixx="6.5e-8" ixy="0" ixz="0" iyy="8.5e-8" iyz="0" izz="8.5e-8"/>
  </inertial>
</link>

<joint name="joint0_arm1" type="continuous">
	<parent link="base_link"/>
	<child link="link1_arm1"/>
	<origin xyz="0 -0.052735026919 0.195" rpy="-2.042035225 0 3.141592654"/>
	<axis xyz="1 0 0"/>
	<!-- callculation X: 0  Y: -70.23..+17.5  Z: 210-15 -->
	<dynamics damping="0.0001"/>
</joint>

<link name="link1_arm1">
	<visual>
		<origin xyz="0 0 0" rpy="0 0 0"/>
		<geometry>
			<!--<box size="0.01 0.01  0.06"/>-->
			<mesh filename="package://eeduro_delta_description/meshes/link1_scaled.dae"/>
		</geometry>
	</visual>
	<inertial>
		<origin xyz="-0.000667579518792749 4.24024711964181e-05 0.0237382053187016" rpy="0 0 0"/>
		<mass value="0.01225732594264"/>
		<inertia	ixx="3.9170528247202e-06"
							ixy="6.88244852580979e-11"
							ixz="-4.1443351708254e-08"
							iyy="3.81032017743918e-06"
							iyz="1.23377194660718e-08" 
							izz="1.78939838618822e-07"/>
	</inertial>
</link>

<gazebo>
	<joint name="gear_arm1" type="gearbox">
		<parent>link_motor_arm1</parent>
		<child>link1_arm1</child>
		<gearbox_reference_body>base_link</gearbox_reference_body>
		<gearbox_ratio>-0.013176411</gearbox_ratio>
		<axis>
			<xyz>1 0 0</xyz>
		</axis>
    <axis2>
      <xyz>1 0 0</xyz>
    </axis2>
	</joint>
</gazebo>

<joint name="joint1_arm1" type="continuous">
	<parent link="link1_arm1"/>
	<child link="link2_arm1"/>
	<origin xyz="0 0 0.05" rpy="-1.919862177 0 0"/>
	<axis xyz="1 0 0"/>
	<dynamics damping="0.00001"/>
</joint>

<link name="link2_arm1">
	<visual>
		<origin xyz="0 0 0" rpy="0 0 0"/>
		<geometry>
			<mesh filename="package://eeduro_delta_description/meshes/link2_scaled.dae"/>
      <!--<box size="0.042 0.006 0.006"/>-->
    </geometry>
	</visual>
  <inertial>
    <origin xyz="-4.65883028011777e-16 0.000173858781653159 5.67176538207829e-17" rpy="0 0 0"/>
    <mass value="0.002676077437253"/>
    <inertia	ixx="2.12767184543771e-08"	
							ixy="-5.53089204125579e-22"
							ixz="-3.40282030897929e-10"
							iyy="5.08472734636316e-07" 
							iyz="1.63502204451954e-23"
							izz="5.19396055186747e-07"/>
  </inertial>
</link>

<joint name="joint2_0_arm1" type="continuous">
	<parent link="link2_arm1"/>
	<child link="link3_0_arm1"/>
	<origin xyz="0.018 0 0" rpy="0 0 -1.570796327"/>
	<axis xyz="1 0 0"/>
	<dynamics damping="0.00001"/>
</joint>
	
<link name="link3_0_arm1">
  <visual>
		<origin xyz="0 0 0" rpy="0 0 0"/>
    <geometry>
			<mesh filename="package://eeduro_delta_description/meshes/link3_scaled.dae"/>
      <!--<box size="0.005 0.005 0.1"/>-->
    </geometry>
  </visual>
  <inertial>
    <origin xyz="4.79435653399733e-15 5.05515762210611e-15 0.05" rpy="0 0 0"/>
    <mass value="0.00303456300894497"/>
    <inertia	ixx="3.21114513230401e-06"
							ixy="-1.39831896086795e-22"
							ixz="-1.65818121965606e-19"
							iyy="3.20896476471281e-06"
							iyz="-7.25104237772119e-20"
							izz="5.81686125403351e-09"/>
  </inertial>
</link>


<joint name="joint2_1_arm1" type="continuous">
  <parent link="link2_arm1"/>
  <child link="link3_1_arm1"/>
  <origin xyz="-0.018 0 0" rpy="0 0 -1.570796327"/>
  <axis xyz="1 0 0"/>
	<dynamics damping="0.00001"/>
</joint>

<link name="link3_1_arm1">
  <visual>
    <origin xyz="0 0 0" rpy="0 0 0"/>
    <geometry>
      <mesh filename="package://eeduro_delta_description/meshes/link3_scaled.dae"/>
      <!--<box size="0.005 0.005 0.1"/>-->
    </geometry>
  </visual>
  <inertial>
    <origin xyz="4.79435653399733e-15 5.05515762210611e-15 0.05" rpy="0 0 0"/>
    <mass value="0.00303456300894497"/>
    <inertia  ixx="3.21114513230401e-06"
              ixy="-1.39831896086795e-22"
              ixz="-1.65818121965606e-19"
              iyy="3.20896476471281e-06"
              iyz="-7.25104237772119e-20"
              izz="5.81686125403351e-09"/>
  </inertial>
</link>

<joint name="joint3_0_arm1" type="continuous">
  <parent link="link3_0_arm1"/>
  <child link="link4_arm1"/>
  <origin xyz="0 0 0.1" rpy="0 0 0"/>
  <axis xyz="1 0 0"/>
	<dynamics damping="0.00001"/>
</joint>

<link name="link4_arm1">
  <visual>
    <origin xyz="0 -0.018 0" rpy="0 0 1.570796327"/>
    <geometry>
			<mesh filename="package://eeduro_delta_description/meshes/link2_scaled.dae"/>
      <!--<box size="0.042 0.006 0.006"/>-->
    </geometry>
  </visual>
  <inertial>
		<origin xyz="-0.00017385878165316 -0.0179999999999995 -5.56154717015503e-17" rpy="0 0 0"/>
    <mass value="0.002676077437253"/>
    <inertia  ixx="5.08472734636316e-07"
              ixy="-5.82921356214306e-22"
              ixz="1.63293841801982e-23"
              iyy="2.12767184543771e-08"
              iyz="-3.40282030897868e-10"
              izz="5.19396055186747e-07"/>
  </inertial>
</link>


<gazebo>
<joint name="joint3_1_arm1" type="revolute">
	<child>link4_arm1</child>
	<parent>link3_1_arm1</parent>
	<pose>0 -0.036 0 0 0 0</pose>
	<axis>
		<use_parent_model_frame>false</use_parent_model_frame>
		<xyz>1 0 0</xyz>
		<limit>
			<lower>-1e+16</lower>
			<upper>1e+16</upper>
		</limit>
		<dynamics>
			<damping>0.00001</damping>
		</dynamics>
	</axis>
</joint>
</gazebo>


<joint name="joint4_arm1" type="continuous">
	<parent link="link4_arm1"/>
	<child link="tool"/>
	<origin xyz="0 -0.018 0" rpy="-0.733038286 0 1.570796327"/>
	<axis xyz="1 0 0"/>
	<dynamics damping="0.00001"/>
</joint>

<link name="tool">
	<visual>
    <origin xyz="0 0 0" rpy="0 0 0"/>
    <geometry>
			<mesh filename="package://eeduro_delta_description/meshes/tool_scaled.dae"/>
    </geometry>
  </visual>
	<collision>
		<origin xyz="0 0 0.023" rpy="1.570796327 0 0"/>
    <geometry>
			<cylinder radius="0.007" length="0.051"/>
    </geometry>
	</collision>
  <inertial>
    <origin xyz="2.59861008225168e-05 0.00192804788388403 0.022995128907788" rpy="0 0 0"/>
    <mass value="0.05741035631797"/>
    <inertia	ixx="1.98534599648007e-05" 
							ixy="-5.03744139689366e-09"
							ixz="8.28383830393447e-10"
							iyy="5.51924419052098e-06" 
							iyz="1.3955126250812e-08" 
							izz="1.98271230263828e-05"/>
  </inertial>
</link>


<!--
<gazebo reference="joint1_arm1">
</gazebo>
-->

<gazebo reference="base_link">
	<selfCollide>true</selfCollide>
</gazebo>

<gazebo reference="tool">
  <selfCollide>true</selfCollide>
</gazebo>


</robot>
